<?xml version="1.0"?>
<robot name="so_arm101_camera">

  <!-- Materials -->
  <material name="white">
    <color rgba="1 1 1 1"/>
  </material>
  
  <material name="black">
    <color rgba="0.2 0.2 0.2 1"/>
  </material>
  
  <material name="red">
    <color rgba="0.8 0.1 0.1 1"/>
  </material>
  
  <material name="camera_material">
    <color rgba="0.1 0.1 0.1 1"/>
  </material>

  <!-- Base Link -->
  <link name="base_link">
    <visual>
      <origin xyz="0 0 0" rpy="0 0 0"/>
      <geometry>
        <mesh filename="assets/base_so101_v2.stl" scale="0.001 0.001 0.001"/>
      </geometry>
      <material name="white"/>
    </visual>
    <collision>
      <origin xyz="0 0 0.025" rpy="0 0 0"/>
      <geometry>
        <cylinder radius="0.06" length="0.05"/>
      </geometry>
    </collision>
    <inertial>
      <mass value="0.5"/>
      <origin xyz="0 0 0.025"/>
      <inertia ixx="0.01" ixy="0" ixz="0" iyy="0.01" iyz="0" izz="0.01"/>
    </inertial>
  </link>

  <!-- Motor Holder Base -->
  <link name="motor_holder_base">
    <visual>
      <origin xyz="0 0 0" rpy="0 0 0"/>
      <geometry>
        <mesh filename="assets/motor_holder_so101_base_v1.stl" scale="0.001 0.001 0.001"/>
      </geometry>
      <material name="black"/>
    </visual>
    <collision>
      <origin xyz="0 0 0.02" rpy="0 0 0"/>
      <geometry>
        <cylinder radius="0.04" length="0.04"/>
      </geometry>
    </collision>
    <inertial>
      <mass value="0.3"/>
      <origin xyz="0 0 0.02"/>
      <inertia ixx="0.005" ixy="0" ixz="0" iyy="0.005" iyz="0" izz="0.005"/>
    </inertial>
  </link>

  <!-- Under Arm -->
  <link name="under_arm">
    <visual>
      <origin xyz="0 0 0" rpy="0 0 0"/>
      <geometry>
        <mesh filename="assets/under_arm_so101_v1.stl" scale="0.001 0.001 0.001"/>
      </geometry>
      <material name="white"/>
    </visual>
    <collision>
      <origin xyz="0 0 0.05" rpy="0 0 0"/>
      <geometry>
        <box size="0.08 0.04 0.1"/>
      </geometry>
    </collision>
    <inertial>
      <mass value="0.4"/>
      <origin xyz="0 0 0.05"/>
      <inertia ixx="0.006" ixy="0" ixz="0" iyy="0.006" iyz="0" izz="0.006"/>
    </inertial>
  </link>

  <!-- Upper Arm -->
  <link name="upper_arm">
    <visual>
      <origin xyz="0 0 0" rpy="0 0 0"/>
      <geometry>
        <mesh filename="assets/upper_arm_so101_v1.stl" scale="0.001 0.001 0.001"/>
      </geometry>
      <material name="white"/>
    </visual>
    <collision>
      <origin xyz="0 0 0.075" rpy="0 0 0"/>
      <geometry>
        <box size="0.06 0.04 0.15"/>
      </geometry>
    </collision>
    <inertial>
      <mass value="0.35"/>
      <origin xyz="0 0 0.075"/>
      <inertia ixx="0.005" ixy="0" ixz="0" iyy="0.005" iyz="0" izz="0.005"/>
    </inertial>
  </link>

  <!-- Rotation Pitch -->
  <link name="rotation_pitch">
    <visual>
      <origin xyz="0 0 0" rpy="0 0 0"/>
      <geometry>
        <mesh filename="assets/rotation_pitch_so101_v1.stl" scale="0.001 0.001 0.001"/>
      </geometry>
      <material name="black"/>
    </visual>
    <collision>
      <origin xyz="0 0 0.03" rpy="0 0 0"/>
      <geometry>
        <cylinder radius="0.025" length="0.06"/>
      </geometry>
    </collision>
    <inertial>
      <mass value="0.2"/>
      <origin xyz="0 0 0.03"/>
      <inertia ixx="0.003" ixy="0" ixz="0" iyy="0.003" iyz="0" izz="0.003"/>
    </inertial>
  </link>

  <!-- Wrist Roll Pitch -->
  <link name="wrist_roll_pitch">
    <visual>
      <origin xyz="0 0 0" rpy="0 0 0"/>
      <geometry>
        <mesh filename="assets/wrist_roll_pitch_so101_v2.stl" scale="0.001 0.001 0.001"/>
      </geometry>
      <material name="white"/>
    </visual>
    <collision>
      <origin xyz="0 0 0.025" rpy="0 0 0"/>
      <geometry>
        <cylinder radius="0.02" length="0.05"/>
      </geometry>
    </collision>
    <inertial>
      <mass value="0.15"/>
      <origin xyz="0 0 0.025"/>
      <inertia ixx="0.002" ixy="0" ixz="0" iyy="0.002" iyz="0" izz="0.002"/>
    </inertial>
  </link>

  <!-- Wrist Roll Follower (End Effector) -->
  <link name="wrist_roll_follower">
    <visual>
      <origin xyz="0 0 0" rpy="0 0 0"/>
      <geometry>
        <mesh filename="assets/wrist_roll_follower_so101_v1.stl" scale="0.001 0.001 0.001"/>
      </geometry>
      <material name="black"/>
    </visual>
    <collision>
      <origin xyz="0 0 0.02" rpy="0 0 0"/>
      <geometry>
        <cylinder radius="0.015" length="0.04"/>
      </geometry>
    </collision>
    <inertial>
      <mass value="0.1"/>
      <origin xyz="0 0 0.02"/>
      <inertia ixx="0.001" ixy="0" ixz="0" iyy="0.001" iyz="0" izz="0.001"/>
    </inertial>
  </link>

  <!-- Camera Link -->
  <link name="camera_link">
    <visual>
      <origin xyz="0 0 0" rpy="0 0 0"/>
      <geometry>
        <box size="0.03 0.03 0.02"/>
      </geometry>
      <material name="camera_material"/>
    </visual>
    <collision>
      <origin xyz="0 0 0" rpy="0 0 0"/>
      <geometry>
        <box size="0.03 0.03 0.02"/>
      </geometry>
    </collision>
    <inertial>
      <mass value="0.05"/>
      <inertia ixx="0.001" ixy="0" ixz="0" iyy="0.001" iyz="0" izz="0.001"/>
    </inertial>
  </link>

  <!-- Joints based on SO-ARM101 kinematics -->
  
  <!-- Joint 1: Base Rotation -->
  <joint name="joint_1" type="revolute">
    <parent link="base_link"/>
    <child link="motor_holder_base"/>
    <origin xyz="0 0 0.05" rpy="0 0 0"/>
    <axis xyz="0 0 1"/>
    <limit lower="-3.14159" upper="3.14159" effort="100" velocity="2.0"/>
    <dynamics damping="0.1" friction="0.1"/>
  </joint>

  <!-- Joint 2: Shoulder Pitch -->
  <joint name="joint_2" type="revolute">
    <parent link="motor_holder_base"/>
    <child link="under_arm"/>
    <origin xyz="0 0 0.04" rpy="0 0 0"/>
    <axis xyz="0 1 0"/>
    <limit lower="-1.5708" upper="1.5708" effort="100" velocity="2.0"/>
    <dynamics damping="0.1" friction="0.1"/>
  </joint>

  <!-- Joint 3: Elbow Pitch -->
  <joint name="joint_3" type="revolute">
    <parent link="under_arm"/>
    <child link="upper_arm"/>
    <origin xyz="0 0 0.1" rpy="0 0 0"/>
    <axis xyz="0 1 0"/>
    <limit lower="-1.5708" upper="1.5708" effort="80" velocity="2.0"/>
    <dynamics damping="0.1" friction="0.1"/>
  </joint>

  <!-- Joint 4: Wrist Pitch -->
  <joint name="joint_4" type="revolute">
    <parent link="upper_arm"/>
    <child link="rotation_pitch"/>
    <origin xyz="0 0 0.15" rpy="0 0 0"/>
    <axis xyz="0 1 0"/>
    <limit lower="-1.5708" upper="1.5708" effort="50" velocity="2.0"/>
    <dynamics damping="0.1" friction="0.1"/>
  </joint>

  <!-- Joint 5: Wrist Roll -->
  <joint name="joint_5" type="revolute">
    <parent link="rotation_pitch"/>
    <child link="wrist_roll_pitch"/>
    <origin xyz="0 0 0.06" rpy="0 0 0"/>
    <axis xyz="1 0 0"/>
    <limit lower="-1.5708" upper="1.5708" effort="30" velocity="2.0"/>
    <dynamics damping="0.1" friction="0.1"/>
  </joint>

  <!-- Joint 6: Wrist Yaw -->
  <joint name="joint_6" type="revolute">
    <parent link="wrist_roll_pitch"/>
    <child link="wrist_roll_follower"/>
    <origin xyz="0 0 0.05" rpy="0 0 0"/>
    <axis xyz="0 0 1"/>
    <limit lower="-3.14159" upper="3.14159" effort="30" velocity="2.0"/>
    <dynamics damping="0.1" friction="0.1"/>
  </joint>

  <!-- Camera Joint -->
  <joint name="camera_joint" type="fixed">
    <parent link="wrist_roll_follower"/>
    <child link="camera_link"/>
    <origin xyz="0 0 0.04" rpy="0 1.5708 0"/>
  </joint>

</robot>