<?xml version="1.0"?>
<robot name="so_arm101_simple">

  <!-- Materials -->
  <material name="white">
    <color rgba="0.9 0.9 0.9 1"/>
  </material>
  
  <material name="black">
    <color rgba="0.2 0.2 0.2 1"/>
  </material>
  
  <material name="camera_material">
    <color rgba="0.1 0.1 0.1 1"/>
  </material>

  <!-- Base Link -->
  <link name="base_link">
    <visual>
      <origin xyz="0 0 0.025" rpy="0 0 0"/>
      <geometry>
        <cylinder radius="0.06" length="0.05"/>
      </geometry>
      <material name="black"/>
    </visual>
    <collision>
      <origin xyz="0 0 0.025" rpy="0 0 0"/>
      <geometry>
        <cylinder radius="0.06" length="0.05"/>
      </geometry>
    </collision>
    <inertial>
      <mass value="0.5"/>
      <origin xyz="0 0 0.025"/>
      <inertia ixx="0.01" ixy="0" ixz="0" iyy="0.01" iyz="0" izz="0.01"/>
    </inertial>
  </link>

  <!-- Link 1: Shoulder -->
  <link name="shoulder_link">
    <visual>
      <origin xyz="0 0 0.05" rpy="0 0 0"/>
      <geometry>
        <box size="0.08 0.04 0.1"/>
      </geometry>
      <material name="white"/>
    </visual>
    <collision>
      <origin xyz="0 0 0.05" rpy="0 0 0"/>
      <geometry>
        <box size="0.08 0.04 0.1"/>
      </geometry>
    </collision>
    <inertial>
      <mass value="0.4"/>
      <origin xyz="0 0 0.05"/>
      <inertia ixx="0.006" ixy="0" ixz="0" iyy="0.006" iyz="0" izz="0.006"/>
    </inertial>
  </link>

  <!-- Link 2: Upper Arm -->
  <link name="upper_arm_link">
    <visual>
      <origin xyz="0 0 0.075" rpy="0 0 0"/>
      <geometry>
        <box size="0.06 0.04 0.15"/>
      </geometry>
      <material name="white"/>
    </visual>
    <collision>
      <origin xyz="0 0 0.075" rpy="0 0 0"/>
      <geometry>
        <box size="0.06 0.04 0.15"/>
      </geometry>
    </collision>
    <inertial>
      <mass value="0.35"/>
      <origin xyz="0 0 0.075"/>
      <inertia ixx="0.005" ixy="0" ixz="0" iyy="0.005" iyz="0" izz="0.005"/>
    </inertial>
  </link>

  <!-- Link 3: Forearm -->
  <link name="forearm_link">
    <visual>
      <origin xyz="0 0 0.06" rpy="0 0 0"/>
      <geometry>
        <box size="0.05 0.035 0.12"/>
      </geometry>
      <material name="white"/>
    </visual>
    <collision>
      <origin xyz="0 0 0.06" rpy="0 0 0"/>
      <geometry>
        <box size="0.05 0.035 0.12"/>
      </geometry>
    </collision>
    <inertial>
      <mass value="0.25"/>
      <origin xyz="0 0 0.06"/>
      <inertia ixx="0.004" ixy="0" ixz="0" iyy="0.004" iyz="0" izz="0.004"/>
    </inertial>
  </link>

  <!-- Link 4: Wrist Pitch -->
  <link name="wrist_pitch_link">
    <visual>
      <origin xyz="0 0 0.025" rpy="0 0 0"/>
      <geometry>
        <cylinder radius="0.025" length="0.05"/>
      </geometry>
      <material name="black"/>
    </visual>
    <collision>
      <origin xyz="0 0 0.025" rpy="0 0 0"/>
      <geometry>
        <cylinder radius="0.025" length="0.05"/>
      </geometry>
    </collision>
    <inertial>
      <mass value="0.15"/>
      <origin xyz="0 0 0.025"/>
      <inertia ixx="0.002" ixy="0" ixz="0" iyy="0.002" iyz="0" izz="0.002"/>
    </inertial>
  </link>

  <!-- Link 5: Wrist Roll -->
  <link name="wrist_roll_link">
    <visual>
      <origin xyz="0 0 0.02" rpy="0 0 0"/>
      <geometry>
        <cylinder radius="0.02" length="0.04"/>
      </geometry>
      <material name="white"/>
    </visual>
    <collision>
      <origin xyz="0 0 0.02" rpy="0 0 0"/>
      <geometry>
        <cylinder radius="0.02" length="0.04"/>
      </geometry>
    </collision>
    <inertial>
      <mass value="0.1"/>
      <origin xyz="0 0 0.02"/>
      <inertia ixx="0.001" ixy="0" ixz="0" iyy="0.001" iyz="0" izz="0.001"/>
    </inertial>
  </link>

  <!-- Link 6: End Effector -->
  <link name="end_effector_link">
    <visual>
      <origin xyz="0 0 0.015" rpy="0 0 0"/>
      <geometry>
        <cylinder radius="0.015" length="0.03"/>
      </geometry>
      <material name="black"/>
    </visual>
    <collision>
      <origin xyz="0 0 0.015" rpy="0 0 0"/>
      <geometry>
        <cylinder radius="0.015" length="0.03"/>
      </geometry>
    </collision>
    <inertial>
      <mass value="0.08"/>
      <origin xyz="0 0 0.015"/>
      <inertia ixx="0.001" ixy="0" ixz="0" iyy="0.001" iyz="0" izz="0.001"/>
    </inertial>
  </link>

  <!-- Camera Link -->
  <link name="camera_link">
    <visual>
      <origin xyz="0 0 0" rpy="0 0 0"/>
      <geometry>
        <box size="0.03 0.03 0.02"/>
      </geometry>
      <material name="camera_material"/>
    </visual>
    <collision>
      <origin xyz="0 0 0" rpy="0 0 0"/>
      <geometry>
        <box size="0.03 0.03 0.02"/>
      </geometry>
    </collision>
    <inertial>
      <mass value="0.05"/>
      <inertia ixx="0.001" ixy="0" ixz="0" iyy="0.001" iyz="0" izz="0.001"/>
    </inertial>
  </link>

  <!-- Joints -->
  
  <!-- Joint 1: Base Rotation -->
  <joint name="joint_1" type="revolute">
    <parent link="base_link"/>
    <child link="shoulder_link"/>
    <origin xyz="0 0 0.05" rpy="0 0 0"/>
    <axis xyz="0 0 1"/>
    <limit lower="-3.14159" upper="3.14159" effort="100" velocity="2.0"/>
    <dynamics damping="0.1" friction="0.1"/>
  </joint>

  <!-- Joint 2: Shoulder Pitch -->
  <joint name="joint_2" type="revolute">
    <parent link="shoulder_link"/>
    <child link="upper_arm_link"/>
    <origin xyz="0 0 0.1" rpy="0 0 0"/>
    <axis xyz="0 1 0"/>
    <limit lower="-1.5708" upper="1.5708" effort="100" velocity="2.0"/>
    <dynamics damping="0.1" friction="0.1"/>
  </joint>

  <!-- Joint 3: Elbow Pitch -->
  <joint name="joint_3" type="revolute">
    <parent link="upper_arm_link"/>
    <child link="forearm_link"/>
    <origin xyz="0 0 0.15" rpy="0 0 0"/>
    <axis xyz="0 1 0"/>
    <limit lower="-1.5708" upper="1.5708" effort="80" velocity="2.0"/>
    <dynamics damping="0.1" friction="0.1"/>
  </joint>

  <!-- Joint 4: Wrist Pitch -->
  <joint name="joint_4" type="revolute">
    <parent link="forearm_link"/>
    <child link="wrist_pitch_link"/>
    <origin xyz="0 0 0.12" rpy="0 0 0"/>
    <axis xyz="0 1 0"/>
    <limit lower="-1.5708" upper="1.5708" effort="50" velocity="2.0"/>
    <dynamics damping="0.1" friction="0.1"/>
  </joint>

  <!-- Joint 5: Wrist Roll -->
  <joint name="joint_5" type="revolute">
    <parent link="wrist_pitch_link"/>
    <child link="wrist_roll_link"/>
    <origin xyz="0 0 0.05" rpy="0 0 0"/>
    <axis xyz="1 0 0"/>
    <limit lower="-1.5708" upper="1.5708" effort="30" velocity="2.0"/>
    <dynamics damping="0.1" friction="0.1"/>
  </joint>

  <!-- Joint 6: Wrist Yaw -->
  <joint name="joint_6" type="revolute">
    <parent link="wrist_roll_link"/>
    <child link="end_effector_link"/>
    <origin xyz="0 0 0.04" rpy="0 0 0"/>
    <axis xyz="0 0 1"/>
    <limit lower="-3.14159" upper="3.14159" effort="30" velocity="2.0"/>
    <dynamics damping="0.1" friction="0.1"/>
  </joint>

  <!-- Camera Joint -->
  <joint name="camera_joint" type="fixed">
    <parent link="end_effector_link"/>
    <child link="camera_link"/>
    <origin xyz="0 0 0.03" rpy="0 1.5708 0"/>
  </joint>

</robot>